Workbook

Sheet 1. Table_of_Contents
B2: Table of Contents
B3: Sheet # | C3: Sheet Name | D3: Table Name | E3: Sheet Description
B4: Sheet 2 | C4: Quantum_System_Configuration | D4: Table S1: Modeled quantum system configurations | E4: Describes the system paramters for the three modeled quantum system configurations
B5: Sheet 3 | C5: Energy_Resource_Calculations | D5: Table S2: Energy and resource calculations for quantum systems | E5: Presents detailed calculations for modeled quantum system configurations in Sheet 2
B6: Sheet 4 | C6: Energy_Resource_Quant_Summary | D6: Table S3: Summary of energy and resource usage for quantum systems | E6: Summarizes the energy and resource consumption of modeled quantum systems in Sheet 3
B7: Sheet 5 | C7: Future_Quantum_Scaling | D7: Table S4: Inputs and assumptions for future scaling of QuACI Table S5: Energy and resource impacts of future scaling of QuACI | E7: Presents calculations on energy and resource impacts of integration of quantum systems with advanced classical computing and digital infrastructure
B8: Sheet 6 | C8: References | D8: Table S5: List of references | E8: List of references noted in this spreadsheet
B10: Citation
B13: Authors
B16: Acknowledgements
B24: Disclaimer: This sheet is password protected to prevent any accidental changes to calculations. To unprotect/unlock the sheet, use the following password: QUEENS@ORNL.
B25: NS: Not protected as of now. Do before submission/finalization.
B27: Key Abbreviations
B28: DR | C28: dilution refrigerator
B29: FTQC | C29: fault tolerant quantum computer
B30: K | C30: Kelvin
B31: kW | C31: kilowatts
B32: mK | C32: milliKelvin
B33: MW | C33: megawatts
B34: PQ | C34: physical qubit
B35: RSA | C35: Rivest-Shamir-Adleman cryptosystem
B36: QuACI | C36: Quantum Accelerated Computing Infrastructure

Sheet 2. Quantum_System_Configuration
B1: Table S1: Modeled quantum system configurations
B2: Quantum System Configuration → | C2: Practical FTQC | D2: Small FTQC | E2: Large FTQC | F2: Notes & Documentation
B3: Example Base Designs → System Parameters ↓ | C3: IBM's System Two (2027+) | D3: IBM's System Two (2033+) | E3: IBM System Two (2033+) scaled to Fermilab's Colossus**, then with improved error correction and higher qubit density
B4: # of logical qubits | C4: 200 | D4: 2000 | E4: 5000 | F4: FTQC needs at least 100 logical qubits, and more likely at least 1,000. Solving complex chemical simulations requires 4,000 or more. IBM's Blue Jay system planned for the 2033+ timeframe claims 2,000 logical qubits, 1 billion gates, advanced error-correction and full fault-tolerance. | H4: Schematic for resource consumption flow paths for a FTQC
B5: Ratio of physical to logical qubits | C5: 500 | D5: =10^3 -> 1000 | E5: 2000 | F5: Values for physical-to-logical qubit ratio of between 500 and 2,000 are reasonable to assume for future FTQC systems at varying levels of error rate, and therefore functionality. Based on Ezratty (2024), Fig. 253, p. 291, and on the best-practices being designed and explored by Google, IBM, and others.
B6: Logical qubit error rate | C6: around 10^-7 | D6: around 10^-12 | E6: around 10^-15 | F6: See Ezratty (2024), Fig. 253, p. 291. According to text on p. 295, an error rate of 10^-15 is needed for RSA-2048 key encryption, and lower for solving complex chemical simulations. These values do not feed into any calculations - for reference purpose only.
B7: # of physical qubits (base level) | C7: =C4*C5 -> 100000 | D7: =D4*D5 -> 2000000 | E7: =E4*E5 -> 10000000 | F7: -
B8: Additional # of physical qubits needed for error-correction | C8: =1*(C7) -> 100000 | D8: =1*(D7) -> 2000000 | E8: =1*(E7) -> 10000000 | F8: Upon discussion with quantum computing experts, the number of physical qubits needed for error-correction is assumed to be equal to the previously calculated number of physical qubits (i.e., 2x the base level of physical qubits). This assumes surface-code style algorithms for error correction, which could potentially improve markedly in the future -- an intense area of research at present.
B9: Total physical qubits needed | C9: =C7+C8 -> 200000 | D9: =D7+D8 -> 4000000 | E9: =E7+E8 -> 20000000 | F9: -
B10: Volume of cryo-chamber (m^3) | C10: 1.7 | D10: 1.7 | E10: 5 | F10: From IBM's reporting, each System Two (Practical and Small FTQC) "cluster" (including 3 dilution refrigerators inside) has a working volume of 1.7 m^3. Fermilab's Colossus (Large FTQC) has a volume of 5.0 m^3 (with 12 dilution refrigerators inside; 10 of them at 20 mK). For cryo-coolers, reference design is based on the Bluefors/Cryomech PT415 unit with a CPA1110 compressor. (https://bluefors.com/products/pulse-tube-cryocoolers/pt415-pulse-tube-cryocooler. Current as of 09/15/2025). For nitrogen and helium liquefaction, reference design is based on the Linde L1610 unit with a 2RS compressor. Based on discussion with cryogenics experts, a L1610 helium liquefier will be able to support the Colossus sized quantum system, i.e., 12 LD400 DRs. (https://assets.linde.com/-/media/global/kryotechnik/kryotechnik/products/datasheet-l1610-lr1630-helium-liquefier-refrigerator.pdf. Current as of 09/15/2025). For dilution refrigerators, reference design is based on the Bluefors LD400 unit. (https://bluefors.com/products/dilution-refrigerator-measurement-systems/ld-dilution-refrigerator-measurement-system/. Current as 09/15/2025). Electricity consumption includes pumping, compression, liquefaction, and slow control systems used for monitoring. In all cases, the lowest temperature achieved within the dilution refrigerators is 10-20 milliKelvin. This is the qubit working temperature.
B11: # of physical qubits per cryo-chamber | C11: =1080*C12 -> 3240 | D11: 25000 | E11: =E13*E12 -> 1200000 | F11: For Practical FTQC, assume that it becomes too challenging to move beyond 1,080 physical qubits per dilution refrigerator (= 9 x 120 qubits per Nighthawk chip). This is similar to Fujitsu's target for the late-2020s (= 1,024 qubits per dilution refrigerator). Each of IBM's System Two clusters (Small FTQC) has 3 DRs; the plan in 2033+ is that each of these clusters will support 25,000 physical qubits = 8,333 physical qubits per dilution fridge. For the Large FTQC, use the value of 120,000 physical qubits per DR from Mohseni et al. (2025); see the caption to Figure 27 of the paper. See Ezratty (2024), p. 415, and IBM's "2025 Development & Innovation Roadmap", for the the IBM numbers. See Fujitsu's "Fujitsu Quantum Computing Strategy (April 2025)" for their expectations.
B12: # of 20-mK dilution refrigerators per cryo-chamber | C12: 3 | D12: 3 | E12: 10 | F12: See note in cell above for the discussion on IBM's System Two (Practical & Small FTQC). See Hollister et al. (2024) for the information on Colossus (Large FTQC); there are 12 dilution refrigerators, but 2 of them operate at higher temperatures (hence, 12-2 = 10 DRs).
B13: # of physical qubits per 20-mK dilution refrigerator | C13: =C11/C12 -> 1080 | D13: =D11/D12 -> 8333.3333 | E13: 120000 | F13: See above notes.
B14: # of cryo-chambers | C14: =C9/C11 -> 61.728395 | D14: =D9/D11 -> 160 | E14: =E9/E11 -> 16.666667 | F14: -
B15: # of dilution refrigerators | C15: =C14*C12 -> 185.18519 | D15: =D14*D12 -> 480 | E15: =E14*E12 -> 166.66667 | F15: -
B16: Energy consumption of cryo-chamber (kW) | C16: =105 -> 105 | D16: =105 -> 105 | E16: 112 | F16: See Ezratty (2024), p. 338. Each of IBM's System Two clusters (Practical and Small FTQC) has 3 dilution refrigerators, and the cluster consumes 105 kW. Estimate for Small FTQC takes its 40,000 kW of electricity consumption for a cooling power of 75 kW @ 4.5 K (based on the ITER nuclear fusion facility) and then proportionally (linearly) downscales it to the size of Colossus (0.2 kW @ 5 K). Estimates for Large FTQC power consumption are derived for a system that uses a cryogenics plant (as with Colossus) instead of pulse-tube cryo-coolers.
B18: Legend for Numerical values in Columns C, D, and E
B19: Assumption (reference and inference provided in Column F)
B20: Calculated Value
B22: ** Colossus refers to Fermilab's experimental cryoplant + cryo-chamber system (not xAI's supercomputer in Memphis, Tennessee, USA).

Sheet 3. Energy_Resource_Calculations
B1: Table S2: Energy and resource calculations for quantum systems
B2: Parameter | C2: Unit | D2: Constants | E2: Unit for Constants | F2: Practical FTQC | G2: Small FTQC | H2: Large FTQC | I2: Notes & Documentation
B3: INPUTS (Control Variables / Base Assumptions)
B4: Computing
B5: Physical Qubits per Logical Qubit | C5: - | F5: 500 | G5: 1000 | H5: 2000
B6: Logical Qubits | C6: qubit | F6: 200 | G6: 2000 | H6: 5000
B7: Time | C7: hours | F7: =365*24 -> 8760 | G7: =365*24 -> 8760 | H7: =365*24 -> 8760
B8: Cryogenics
B9: Energy consumption of cryo-chamber | C9: kW | F9: 105 | G9: 105 | H9: 112
B10: Volume of cryo-chamber | C10: m^3 | F10: 1.7 | G10: 1.7 | H10: 5
B11: # of 20- K dilution refrigerators per cryo-chamber | F11: 3 | G11: 3 | H11: 10
B12: PQ / Cryochamber | F12: =1080*F11 -> 3240 | G12: 25000 | H12: 1200000
B13: Control Electronics
C14: W/qubit | F14: =5 -> 5 | G14: =5.2/1000 -> 0.0052 | H14: =5.2/1000 -> 0.0052 | I14: Potocnik et al. (2025) cites Yoo et al. (2023) value of 5 W/qubit. This is consistent with control electronics operating at room temperatures. According to Geck et al. (2025) on p. 2: “The power consumption per qubit for the spin qubit controllers is estimated to be in the range of 1.7 - 5.2mW/qubit with a frequency spacing between 31.3-125 MHz. All electronics are placed at 3-4 K.” Yoo et al. (2023) – also say that < 4 mW/qubit is possible when the control electronics are located in the cryogenic chamber and at temperatures of 3 K. Their higher value of 5 W/qubit is for control electronics located in room temperature environment. Thus, assume a higher value of 5 W/qubit for less optimistic cases (this is consistent with situating control electronics outside cryo-chamber and thus operating at room temperature). Then, assume lower value of 0.0052 W/qubit for more optimistic cases (this is consistent with situating control electronics inside cryo-chamber and thus operating at temperatures of 3-4 K).
B15: CALCULATED PARAMETERS
B16: Computing
B17: Physical Qubits (total, including error correction) | C17: Qubit | D17: 2 | F17: =$D$17*F6*F5 -> 200000 | G17: =$D$17*G6*G5 -> 4000000 | H17: =$D$17*H6*H5 -> 20000000
B18: Cryogenics
B19: # of physical qubits per 20-mK dilution refrigerator | F19: =F12/F11 -> 1080 | G19: =G12/G11 -> 8333.3333 | H19: =H12/H11 -> 120000
B20: # Cryochambers | F20: =F17/F12 -> 61.728395 | G20: =G17/G12 -> 160 | H20: =H17/H12 -> 16.666667
B21: # DR | F21: =F20*F11 -> 185.18519 | G21: =G20*G11 -> 480 | H21: =H20*H11 -> 166.66667
B22: ELECTRIC POWER CONSUMPTION
B23: Control electronics | C23: kW | F23: =F14*F17/1000 -> 1000 | G23: =G14*G17/1000 -> 20.8 | H23: =H14*H17/1000 -> 104
B24: Cryogenics | C24: kW | F24: =(F25)*F17/1000 -> 6481.4815 | G24: =(G25)*G17/1000 -> 16800 | H24: =(H25)*H17/1000 -> 1866.6667
B25: Cryochamber (W/PQ) | C25: W/PQ | F25: =F9*1000/F12 -> 32.407407 | G25: =G9*1000/G12 -> 4.2 | H25: =H9*1000/H12 -> 0.093333333
B26: Cooling water circulation | C26: kW | F26: =F46 -> 2466 | G26: =G46 -> 5754 | H26: =H46 -> 1644
B27: Baseload | C27: kW | D27: 0.1 | F27: =(F23+F24+F26)*$D$27 -> 994.74815 | G27: =(G23+G24+G26)*$D$27 -> 2257.48 | H27: =(H23+H24+H26)*$D$27 -> 361.46667 | I27: Assumed 10% of the total power consumption.
B28: Miscellaneous | C28: kW | D28: 0.1 | F28: =(F23+F24+F26)*$D$28 -> 994.74815 | G28: =(G23+G24+G26)*$D$28 -> 2257.48 | H28: =(H23+H24+H26)*$D$28 -> 361.46667 | I28: Micellaneous power consumption is from lighting, heating, ventilation, and cooling requirements of the buildings themselves (not the computing equipment). Assumed 10% of the total power consumption. DOE (2015). An assessment of energy technologies and research opportunities. Quadrennial Technology Review. United States Department of Energy, 12-19. (https://www.energy.gov/sites/prod/files/2017/03/f34/qtr-2015-chapter5.pdf#page=3.18) Lighting: https://www.eia.gov/tools/faqs/faq.php?id=99&t=3
B29: Total Power Consumption | C29: kW | F29: =SUM(F23:F24,F26:F28) -> 11936.978 | G29: =SUM(G23:G24,G26:G28) -> 27089.76 | H29: =SUM(H23:H24,H26:H28) -> 4337.6
B30: Power consumption per Physical Qubit | C30: W/Qubit | F30: =F29*1000/F17 -> 59.684889 | G30: =G29*1000/G17 -> 6.77244 | H30: =H29*1000/H17 -> 0.21688
B31: Annual Electricity Consumption | C31: MWh | F31: =F29*F7/1000 -> 104567.93 | G31: =G29*G7/1000 -> 237306.3 | H31: =H29*H7/1000 -> 37997.376
B32: COOLING WATER CIRCULATION
B33: Helium Liquefier (achieving ~4K) | C33: gal/min | D33: 15 | F33: =$D$33*F20 -> 925.92593 | G33: =$D$33*G20 -> 2400 | H33: =$D$33*H20 -> 250 | I33: Assuming Linde L1610 Liquefier with RSS Compressor, that is water cooled, 15 gpm at 75 deg F max and 45 psig supply pressure (57 lpm at 24 deg C and 310 kPa). Reference: https://assets.linde.com/-/media/global/kryotechnik/kryotechnik/products/datasheet-l1610-lr1630-helium-liquefier-refrigerator.pdf
B34: Pulsetube cryocooler (achieving 2K) | C34: gal/min | D34: 3 | F34: =$D$34*F21 -> 555.55556 | G34: =$D$34*G21 -> 1440 | H34: =$D$34*H21 -> 500 | I34: Assuming Bluefors/Cryomech PT415 Pulse Tube Cryocooler @ 3 gal/min. Reference: https://bluefors.com/products/pulse-tube-cryocoolers/pt415-pulse-tube-cryocooler/
B35: Total | C35: gal/min | F35: =SUM(F33:F34) -> 1481.4815 | G35: =SUM(G33:G34) -> 3840 | H35: =SUM(H33:H34) -> 750
B36: Chiller Calcs
B37: Incoming Temperature | C37: deg F | D37: 55.4 | I37: Based on private conversations with experts who have previously conducted an analysis of cooling water needs for a potential quantum facility in the U.S. Also, agrees with the note in Row 33 for the helium liquefier.
B38: Outgoing Temperature | C38: deg F | D38: 39.2 | I38: Based on private conversations with experts who have previously conducted an analysis of cooling water needs for a potential quantum facility in the U.S.
B39: Sizing Factor | D39: 1.2 | I39: Typically, chillers are oversized by 20% for safety margin.
B40: Calculated Chiller capacity | C40: ton | F40: =CEILING((F35*60*8.33*($D$37-$D$38)*$D$39)/12000,500) -> 1500 | G40: =CEILING((G35*60*8.33*($D$37-$D$38)*$D$39)/12000,500) -> 3500 | H40: =CEILING((H35*60*8.33*($D$37-$D$38)*$D$39)/12000,500) -> 1000 | I40: Chiller tonnage (nameplate) is in 500 ton increments. Reference: Table 3 from USEPA (2017). https://www.epa.gov/sites/default/files/2017-12/documents/ws-commercialbuildings-waterscore-mechanical-systems-guide.pdf. Chiller sizing calculations based on: https://waterchillers.com/chiller-resources/sizing-information/.
...

Sheet 4.Energy_Resource_Quant_Summary
B1: Table S3: Summary of energy and resource usage for quantum systems
B2: Parameter | C2: Unit | D2: Practical FTQC | E2: Small FTQC | F2: Large FTQC
B3: Physical Qubits | C3: # | D3: ='3. Energy_Resource_Calculations'!F17 -> 200000 | E3: ='3. Energy_Resource_Calculations'!G17 -> 4000000 | F3: ='3. Energy_Resource_Calculations'!H17 -> 20000000
B4: Electricity Consumption
B5: Control Electronics | C5: kW | D5: ='3. Energy_Resource_Calculations'!F23 -> 1000 | E5: ='3. Energy_Resource_Calculations'!G23 -> 20.8 | F5: ='3. Energy_Resource_Calculations'!H23 -> 104
B6: Cryogenics | C6: kW | D6: ='3. Energy_Resource_Calculations'!F24 -> 6481.4815 | E6: ='3. Energy_Resource_Calculations'!G24 -> 16800 | F6: ='3. Energy_Resource_Calculations'!H24 -> 1866.6667
B7: Cooling Water Circulation | C7: kW | D7: ='3. Energy_Resource_Calculations'!F26 -> 2466 | E7: ='3. Energy_Resource_Calculations'!G26 -> 5754 | F7: ='3. Energy_Resource_Calculations'!H26 -> 1644
B8: Baseload IT | C8: kW | D8: ='3. Energy_Resource_Calculations'!F27 -> 994.74815 | E8: ='3. Energy_Resource_Calculations'!G27 -> 2257.48 | F8: ='3. Energy_Resource_Calculations'!H27 -> 361.46667
B9: Miscellaneous | C9: kW | D9: ='3. Energy_Resource_Calculations'!F28 -> 994.74815 | E9: ='3. Energy_Resource_Calculations'!G28 -> 2257.48 | F9: ='3. Energy_Resource_Calculations'!H28 -> 361.46667
B10: Total | C10: MW | D10: =SUM(D5:D9)/1000 -> 11.936978 | E10: =SUM(E5:E9)/1000 -> 27.08976 | F10: =SUM(F5:F9)/1000 -> 4.3376
B11: Per Unit
B12: Control Electronics | C12: W/qubit | D12: =D5*1000/D$3 -> 5 | E12: =E5*1000/E$3 -> 0.0052 | F12: =F5*1000/F$3 -> 0.0052
B13: Cryogenics | C13: W/qubit | D13: =D6*1000/D$3 -> 32.407407 | E13: =E6*1000/E$3 -> 4.2 | F13: =F6*1000/F$3 -> 0.093333333
B14: Cooling Water Circulation | C14: W/qubit | D14: =D7*1000/D$3 -> 12.33 | E14: =E7*1000/E$3 -> 1.4385 | F14: =F7*1000/F$3 -> 0.0822
B15: Baseload IT | C15: W/qubit | D15: =D8*1000/D$3 -> 4.9737407 | E15: =E8*1000/E$3 -> 0.56437 | F15: =F8*1000/F$3 -> 0.018073333
B16: Miscellaneous | C16: W/qubit | D16: =D9*1000/D$3 -> 4.9737407 | E16: =E9*1000/E$3 -> 0.56437 | F16: =F9*1000/F$3 -> 0.018073333
B17: Total | C17: W/qubit | D17: =D10*1000000/D$3 -> 59.684889 | E17: =E10*1000000/E$3 -> 6.77244 | F17: =F10*1000000/F$3 -> 0.21688
B18: % Contribution
B19: Control Electronics | C19: % | D19: =D5/(1000*D$10) -> 0.083773298 | E19: =E5/(1000*E$10) -> 0.0007678178 | F19: =F5/(1000*F$10) -> 0.023976392
B20: Cryogenics | C20: % | D20: =D6/(1000*D$10) -> 0.54297508 | E20: =E6/(1000*E$10) -> 0.62016053 | F20: =F6/(1000*F$10) -> 0.43034551
B21: Cooling Water Circulation | C21: % | D21: =D7/(1000*D$10) -> 0.20658495 | E21: =E7/(1000*E$10) -> 0.21240498 | F21: =F7/(1000*F$10) -> 0.37901143
B22: Baseload IT | C22: % | D22: =D8/(1000*D$10) -> 0.083333333 | E22: =E8/(1000*E$10) -> 0.083333333 | F22: =F8/(1000*F$10) -> 0.083333333
B23: Miscellaneous | C23: % | D23: =D9/(1000*D$10) -> 0.083333333 | E23: =E9/(1000*E$10) -> 0.083333333 | F23: =F9/(1000*F$10) -> 0.083333333
B24: Total | C24: % | D24: =D10/D$10 -> 1 | E24: =E10/E$10 -> 1 | F24: =F10/F$10 -> 1
B25: Resource Consumption
B26: Nitrogen | C26: million liters per year (gas at 0 °C and 1 atm) | D26: ='3. Energy_Resource_Calculations'!F51 -> 5243.0222 | E26: ='3. Energy_Resource_Calculations'!G51 -> 13589.914 | F26: ='3. Energy_Resource_Calculations'!H51 -> 4718.72
B27: 3He | C27: liters (gas at 0 °C and 1 atm) (stock/inventory) | D27: ='3. Energy_Resource_Calculations'!F54 -> 3333.3333 | E27: ='3. Energy_Resource_Calculations'!G54 -> 8640 | F27: ='3. Energy_Resource_Calculations'!H54 -> 3000
B28: 4He | C28: liters (liquid at -269 °C) (stock/inventory) | D28: ='3. Energy_Resource_Calculations'!F53 -> 15432.099 | E28: ='3. Energy_Resource_Calculations'!G53 -> 40000 | F28: ='3. Energy_Resource_Calculations'!H53 -> 13888.889
B29: Water | C29: million liters per year | D29: =365*CONVERT('3. Energy_Resource_Calculations'!F43,"gal","l") -> 44.76628 | E29: =365*CONVERT('3. Energy_Resource_Calculations'!G43,"gal","l") -> 104.45465 | F29: =365*CONVERT('3. Energy_Resource_Calculations'!H43,"gal","l") -> 29.844187
B30: Water | C30: million gallons per day | D30: ='3. Energy_Resource_Calculations'!F43 -> 0.0324 | E30: ='3. Energy_Resource_Calculations'!G43 -> 0.0756 | F30: ='3. Energy_Resource_Calculations'!H43 -> 0.0216

Sheet 5. Future_Quantum_Scaling
B1: Table S4: Inputs and assumptions for future scaling of QuACI
B2: Inputs and Assumptions | C2: Values | D2: Notes & Documentation | H2: Legend for Numerical values in Table S4 | L2: Graphs
B3: Base year | C3: 2025 | D3: Most recent statistics on U.S. data centers are available in this year. | H3: Assumption (reference and inference provided in cells labeled as "Notes") | L3: Electric Power | T3: Water
B4: Future year | C4: 2045 | D4: Representative future year in the 2040s | H4: Calculated Value
B5: # Advanced data centers | C5: 68 | D5: Advanced data centers include "Datacenter type" labeled as "Cloud", "Crypto Mining", "Hyperscale" from the S&P Global Data that were built solely in 2024. | H5: Notes
B6: # Hyper-scalar data centers/yr | C6: 75 | D6: Assumed based on S&P Global Data's 68 new data centers in 2024 and 74 (54% of 137 new data centers in the USA as of March 2025, Synergy Research Group as of March 2025; https://www.srgresearch.com/articles/hyperscale-data-center-count-hits-1136-average-size-increases-us-accounts-for-54-of-total-capacity)
B7: 2045 Scenario 1: Low penetration of QuACI | C7: 0.1 | D7: Assuming 10% of advanced digital infrastructure built between 2026 and 2045 will have some variant of FTQC modeled in Sheet 2.
B8: 2045 Scenario 2: High penetration of QuACI | C8: 1 | D8: Assuming 100% of advanced digital infrastructure built between 2026 and 2045 will have some variant of FTQC modeled in Sheet 2.
B9: FTQC mix in 2045 QuACI | C9: Mix 1 | D9: Mix 2 | E9: Mix 3 | F9: Notes
B10: Practical FTQC | C10: 1 | D10: 0 | E10: 0 | F10: Mixes define the combined deployment of Practical, Small FTQC, and Large FTQC for a future scenario.
B11: Small FTQC | C11: 0 | D11: 1 | E11: 0 | L11: Liquid Nitrogen | T11: Liquid Helium-4
B12: Large FTQC | C12: 0 | D12: 0 | E12: 1
B13: Possible digital infrastructure in 2040s | C13: Values | D13: Notes
B14: # Advanced data centers | C14: =(C6*(C4-C3)) -> 1500 | D14: Typically, systems are designed to have redundant (or backup) equipment to assist with production downtime (intentional and/or unexpected). We assume the availability of at least one additional QuACI system (2N redundancy) for risk tolerance. As with other existing computing infrastructure, a future well integrated QuACI will have the capability to transfer computing tasks to network-connected QuACIs (if low latency) to help with efficient operations.
B15: # QuACI in 2045 Scenario 1 | C15: =ROUNDUP(C7*C14,0) -> 150
B16: # QuACI in 2045 Scenario 2 | C16: =C8*C14 -> 1500
B17: Scenario 1 FTQC mix in 2045 QuACI | C17: Mix 1 | D17: Mix 2 | E17: Mix 3 | F17: # Redundant facilities
B18: Practical FTQC | C18: =ROUNDUP(C10*$C$15,0) -> 150 | D18: =ROUNDUP(D10*$C$15,0) -> 0 | E18: =ROUNDUP(E10*$C$15,0) -> 0 | F18: 2
B19: Small FTQC | C19: =ROUNDUP(C11*$C$15,0) -> 0 | D19: =ROUNDUP(D11*$C$15,0) -> 150 | E19: =ROUNDUP(E11*$C$15,0) -> 0 | F19: 2
B20: Large FTQC | C20: =ROUNDUP(C12*$C$15,0) -> 0 | D20: =ROUNDUP(D12*$C$15,0) -> 0 | E20: =ROUNDUP(E12*$C$15,0) -> 150 | F20: 2
B21: Scenario 2 FTQC mix in 2045 QuACI | C21: Mix 1 | D21: Mix 2 | E21: Mix 3 | F21: # Redundant facilities
B22: Practical FTQC | C22: =ROUNDUP(C10*$C$16,0) -> 1500 | D22: =ROUNDUP(D10*$C$16,0) -> 0 | E22: =ROUNDUP(E10*$C$16,0) -> 0 | F22: 2
B23: FTQC (Small) | C23: =ROUNDUP(C11*$C$16,0) -> 0 | D23: =ROUNDUP(D11*$C$16,0) -> 1500 | E23: =ROUNDUP(E11*$C$16,0) -> 0 | F23: 2 | L23: Isotope Helium-3 | W23: AI Data Centers | X23: Quantum Accelerated Computing Infrastructure (QuACI)
B24: FTQC (Large) | C24: =ROUNDUP(C12*$C$16,0) -> 0 | D24: =ROUNDUP(D12*$C$16,0) -> 0 | E24: =ROUNDUP(E12*$C$16,0) -> 1500 | F24: 2 | V24: 2025 | W24: 359 | X24: 0
U25: 2045 | V25: Low Penetration | W25: =C14-C15 -> 1350 | X25: =C15 -> 150
B26: Table S5: Energy and resource impacts of future scaling of QuACI | V26: High Penetration | W26: 0 | X26: =C16 -> 1500
B27: Parameter | C27: Unit | D27: Mix 1 | E27: Mix 2 | F27: Mix 3 | G27: Mix 1 | H27: Mix 2 | I27: Mix 3
D28: Low Penetration | G28: High Penetration
B30: Physical Qubits | C30: # | D30: =SUM(D31:D33) -> 60000000 | E30: =SUM(E31:E33) -> 1200000000 | F30: =SUM(F31:F33) -> 6000000000 | G30: =SUM(G31:G33) -> 600000000 | H30: =SUM(H31:H33) -> 12000000000 | I30: =SUM(I31:I33) -> 60000000000
B31: Practical FTQC | C31: # | D31: ='4.Energy_Resource_Quant_Summary'!D3*$C$18*$F$18 -> 60000000 | E31: ='4.Energy_Resource_Quant_Summary'!D3*$D$18*$F$18 -> 0 | F31: ='4.Energy_Resource_Quant_Summary'!D3*$E$18*$F$18 -> 0 | G31: ='4.Energy_Resource_Quant_Summary'!D3*$C$22*$F$22 -> 600000000 | H31: ='4.Energy_Resource_Quant_Summary'!D3*$D$22*$F$22 -> 0 | I31: ='4.Energy_Resource_Quant_Summary'!D3*$E$22*$F$22 -> 0
B32: Small FTQC | C32: # | D32: ='4.Energy_Resource_Quant_Summary'!E3*$C$19*$F$19 -> 0 | E32: ='4.Energy_Resource_Quant_Summary'!E3*$D$19*$F$19 -> 1200000000 | F32: ='4.Energy_Resource_Quant_Summary'!E3*$E$19*$F$19 -> 0 | G32: ='4.Energy_Resource_Quant_Summary'!E3*$C$23*$F$23 -> 0 | H32: ='4.Energy_Resource_Quant_Summary'!E3*$D$23*$F$23 -> 12000000000 | I32: ='4.Energy_Resource_Quant_Summary'!E3*$E$23*$F$23 -> 0
B33: Large FTQC | C33: # | D33: ='4.Energy_Resource_Quant_Summary'!F3*$C$20*$F$20 -> 0 | E33: ='4.Energy_Resource_Quant_Summary'!F3*$D$20*$F$20 -> 0 | F33: ='4.Energy_Resource_Quant_Summary'!F3*$E$20*$F$20 -> 6000000000 | G33: ='4.Energy_Resource_Quant_Summary'!F3*$C$24*$F$24 -> 0 | H33: ='4.Energy_Resource_Quant_Summary'!F3*$D$24*$F$24 -> 0 | I33: ='4.Energy_Resource_Quant_Summary'!F3*$E$24*$F$24 -> 60000000000
B34: Electric Power Consumption | C34: GW | D34: =SUM(D35:D37) -> 3.5810933 | E34: =SUM(E35:E37) -> 8.126928 | F34: =SUM(F35:F37) -> 1.30128 | G34: =SUM(G35:G37) -> 35.810933 | H34: =SUM(H35:H37) -> 81.26928 | I34: =SUM(I35:I37) -> 13.0128
B35: Practical FTQC | C35: GW | D35: =0.001*'4.Energy_Resource_Quant_Summary'!D10*$C$18*$F$18 -> 3.5810933 | E35: =0.001*'4.Energy_Resource_Quant_Summary'!D10*$D$18*$F$18 -> 0 | F35: =0.001*'4.Energy_Resource_Quant_Summary'!D10*$E$18*$F$18 -> 0 | G35: =0.001*'4.Energy_Resource_Quant_Summary'!D10*$C$22*$F$22 -> 35.810933 | H35: =0.001*'4.Energy_Resource_Quant_Summary'!D10*$D$22*$F$22 -> 0 | I35: =0.001*'4.Energy_Resource_Quant_Summary'!D10*$E$22*$F$22 -> 0
B36: Small FTQC | C36: GW | D36: =0.001*'4.Energy_Resource_Quant_Summary'!E10*$C$19*$F$19 -> 0 | E36: =0.001*'4.Energy_Resource_Quant_Summary'!E10*$D$19*$F$19 -> 8.126928 | F36: =0.001*'4.Energy_Resource_Quant_Summary'!E10*$E$19*$F$19 -> 0 | G36: =0.001*'4.Energy_Resource_Quant_Summary'!E10*$C$23*$F$23 -> 0 | H36: =0.001*'4.Energy_Resource_Quant_Summary'!E10*$D$23*$F$23 -> 81.26928 | I36: =0.001*'4.Energy_Resource_Quant_Summary'!E10*$E$23*$F$23 -> 0
B37: Large FTQC | C37: GW | D37: =0.001*'4.Energy_Resource_Quant_Summary'!F10*$C$20*$F$20 -> 0 | E37: =0.001*'4.Energy_Resource_Quant_Summary'!F10*$D$20*$F$20 -> 0 | F37: =0.001*'4.Energy_Resource_Quant_Summary'!F10*$E$20*$F$20 -> 1.30128 | G37: =0.001*'4.Energy_Resource_Quant_Summary'!F10*$C$24*$F$24 -> 0 | H37: =0.001*'4.Energy_Resource_Quant_Summary'!F10*$D$24*$F$24 -> 0 | I37: =0.001*'4.Energy_Resource_Quant_Summary'!F10*$E$24*$F$24 -> 13.0128
B38: Other Resources
B39: Nitrogen | C39: million liters per year (gas at 0 °C and 1 atm) | D39: =SUM(D40:D42) -> 1572906.7 | E39: =SUM(E40:E42) -> 4076974.1 | F39: =SUM(F40:F42) -> 1415616 | G39: =SUM(G40:G42) -> 15729067 | H39: =SUM(H40:H42) -> 40769741 | I39: =SUM(I40:I42) -> 14156160
B40: Practical FTQC | C40: million liters per year (gas at 0 °C and 1 atm) | D40: ='4.Energy_Resource_Quant_Summary'!D26*$C$18*$F$18 -> 1572906.7 | E40: ='4.Energy_Resource_Quant_Summary'!D26*$D$18*$F$18 -> 0 | F40: ='4.Energy_Resource_Quant_Summary'!D26*$E$18*$F$18 -> 0 | G40: ='4.Energy_Resource_Quant_Summary'!D26*$C$22*$F$22 -> 15729067 | H40: ='4.Energy_Resource_Quant_Summary'!D26*$D$22*$F$22 -> 0 | I40: ='4.Energy_Resource_Quant_Summary'!D26*$E$22*$F$22 -> 0
B41: Small FTQC | C41: million liters per year (gas at 0 °C and 1 atm) | D41: ='4.Energy_Resource_Quant_Summary'!E26*$C$19*$F$19 -> 0 | E41: ='4.Energy_Resource_Quant_Summary'!E26*$D$19*$F$19 -> 4076974.1 | F41: ='4.Energy_Resource_Quant_Summary'!E26*$E$19*$F$19 -> 0 | G41: ='4.Energy_Resource_Quant_Summary'!E26*$C$23*$F$23 -> 0 | H41: ='4.Energy_Resource_Quant_Summary'!E26*$D$23*$F$23 -> 40769741 | I41: ='4.Energy_Resource_Quant_Summary'!E26*$E$23*$F$23 -> 0
...

Sheet 6. References
B2: References
B3: 1 | C3: CoreSite. 2025. “What Is Data Center Redundancy? N, N+1, 2N, 2N+1.” https://www.coresite.com/blog/data-center-redundancy-n-1-vs-2n-1.
B4: 2 | C4: DOE. 2015. An Assessment of Energy Technologies and Research Opportunities. Quadrennial Technology Review. United States Department of Energy. https://www.energy.gov/sites/prod/files/2017/03/f34/qtr-2015-chapter5.pdf#page=2.27.
B5: 3 | C5: Ezratty, Olivier. 2024. Understanding Quantum Technologies 2024. https://www.oezratty.net/wordpress/2024/understanding-quantum-technologies-2024/.
B6: 4 | C6: Hollister, Matthew I, Ram C Dhuley, Christopher James, and Grzegorz L Tatkowski. 2024. “An Update on the Colossus mK Platform at Fermilab.” IOP Conference Series: Materials Science and Engineering 1302 (1): 012030. https://doi.org/10.1088/1757-899X/1302/1/012030.
B7: 5 | C7: IBM. 2025. “IBM Quantum Roadmap.” https://www.ibm.com/roadmaps/quantum/2030/www.ibm.com/roadmaps/quantum/2030.
B8: 6 | C8: James, C., M. Hollister, G. Tatkowski, and R. Dhuley. 2023. “Helium-3 Piping and Gas Handling Implementation for the Colossus Milli-Kelvin Platform at Fermilab.” Fermilab. https://lss.fnal.gov/archive/2023/poster/fermilab-poster-23-007-sqms.pdf.
B9: 7 | C9: Lei, Nuoa, Jun Lu, Arman Shehabi, and Eric Masanet. 2025. “The Water Use of Data Center Workloads: A Review and Assessment of Key Determinants.” Resources, Conservation and Recycling 219 (June): 108310. https://doi.org/10.1016/j.resconrec.2025.108310.
B10: 8 | C10: Mohseni, Masoud, Artur Scherer, K. Grace Johnson, et al. 2025. “How to Build a Quantum Supercomputer: Scaling from Hundreds to Millions of Qubits.” arXiv:2411.10406. Preprint, arXiv, January 31. https://doi.org/10.48550/arXiv.2411.10406.
B11: 9 | C11: Potočnik, Anton. 2025. “How to Scale the Electronic Control Systems of a Quantum Computer.” Nature Electronics 8 (1): 3–4. https://doi.org/10.1038/s41928-024-01331-9.
B12: 10 | C12: S&P Global Market Intelligence. 2025. “Datacenter KnowledgeBase: Q4 2024 Update.”
B13: 11 | C13: Yoo, Juhwan, Zijun Chen, Frank Arute, et al. 2023. “34.2 A 28-Nm Bulk-CMOS IC for Full Control of a Superconducting Quantum Processor Unit-Cell.” 2023 IEEE International Solid-State Circuits Conference (ISSCC), February, 506–8. https://doi.org/10.1109/ISSCC42615.2023.10067292.
B14: 12 | C14: Ehrhard, R., & Murphy, J. (2009). Driving energy efficiency in the US Water & Wastewater industry by focusing on operating and maintenance cost reductions. Energy, 25, 40.
B17: System Design References from Vendor (Current as of 09/15/2025)
B18: 1 | C18: Bluefors LD400 Dilution Refrigerator. https://bluefors.com/products/dilution-refrigerator-measurement-systems/ld-dilution-refrigerator-measurement-system/.
B19: 2 | C19: PT415 Pulse Tube Cryocooler. https://bluefors.com/products/pulse-tube-cryocoolers/pt415-pulse-tube-cryocooler/
B20: 3 | C20: Linde L161 helium liquefier/refrigerator. https://assets.linde.com/-/media/global/kryotechnik/kryotechnik/products/datasheet-l1610-lr1630-helium-liquefier-refrigerator.pdf
B22: General Note: All webpage links noted in the entire excel workobook are active links as of 09/15/2025.
